<?xml version="1.0"?>
<robot name="turobot">

  <link name="base_link">   
    <collision>
         <geometry>
        <box size="0.01 0.01 0.01"/>
      </geometry>
      <origin rpy="0 0 0" xyz="0 0 .48"/>
    </collision>   
  </link>
  <link name="chassis">
    <visual>
      <geometry>
        <mesh filename="package://myrobot_discription/meshes/car_019.dae" scale="1 1 1"/>
      </geometry>
      <origin rpy="0 0 -1.5707" xyz="0 0 .48"/>
    </visual>
    
    <collision>
         <geometry>
        <box size="3.8 1.63 0.6"/>
      </geometry>
      <origin rpy="0 0 0" xyz="0 0 0.3"/>
    </collision>
    
    <inertial>
      <origin xyz="0.7 0 1" rpy="0 0 0"/>
      <mass value="0.6"/>
      <inertia
        ixx="1" ixy="0.0" ixz="0.0"
        iyy="1" iyz="0.0"
        izz="1"/>
    </inertial>   
  </link>
  
  <link name="left_front">
    <collision>
     <geometry>
        <cylinder length="0.05" radius="0.31"/>
      </geometry>
      
      <surface>
            <friction>
              <ode>
                <mu>10000</mu>
                <mu2>100000</mu2>
              </ode>
            </friction>
        </surface>
        
      <origin rpy="0 1.5707 1.5707" xyz="0 0 0"/>
    </collision>
    
    <inertial>
      <origin xyz="0 0 0" rpy="0 1.5707 1.5707"/>
      <mass value="1"/>
      <inertia
        ixx="0.01" ixy="0.0" ixz="0.0"
        iyy="0.01" iyz="0.0"
        izz="0.01"/>
    </inertial>   
  </link>
  
  <link name="left_rear">
    <collision>
         <geometry>
        <cylinder length="0.05" radius="0.31"/>
      </geometry>
      
      <surface>
            <friction>
              <ode>
                <mu>0</mu>
                <mu2>0</mu2>
              </ode>
            </friction>
        </surface>
        
      <origin rpy="0 1.5707 1.5707" xyz="0 0 0"/>
    </collision> 
    
    <inertial>
      <origin xyz="0 0 0" rpy="0 1.5707 1.5707"/>
      <mass value="1"/>
      <inertia
        ixx="0.01" ixy="0.0" ixz="0.0"
        iyy="0.01" iyz="0.0"
        izz="0.01"/>
    </inertial>  
  </link>
  
  <link name="right_front">
    <collision>
         <geometry>
        <cylinder length="0.05" radius="0.31"/>
      </geometry>
      
      <surface>
            <friction>
              <ode>
                <mu>10000</mu>
                <mu2>10000</mu2>
              </ode>
            </friction>
        </surface>
        
      <origin rpy="0 1.5707 1.5707" xyz="0 0 0"/>
    </collision>  
    
    <inertial>
      <origin xyz="0 0 0" rpy="0 1.5707 1.5707"/>
      <mass value="1"/>
      <inertia
        ixx="0.01" ixy="0.0" ixz="0.0"
        iyy="0.01" iyz="0.0"
        izz="0.01"/>
    </inertial> 
  </link>
  
  <link name="right_rear">
    <collision>
         <geometry>
        <cylinder length="0.05" radius="0.31"/>
      </geometry>
      
      <surface>
            <friction>
              <ode>
                <mu>0</mu>
                <mu2>0</mu2>
              </ode>
            </friction>
        </surface>
        
      <origin rpy="0 1.5707 1.5707" xyz="0 0 0"/>
    </collision>  
    
    <inertial>
      <origin xyz="0 0 0" rpy="0 1.5707 1.5707"/>
      <mass value="1"/>
      <inertia
        ixx="0.01" ixy="0.0" ixz="0.0"
        iyy="0.01" iyz="0.0"
        izz="0.01"/>
    </inertial> 
  </link>
  <joint name="chassis_hinge" type="fixed">
        <parent link="base_link"/>
        <child link="chassis"/>
      </joint>
  <joint name="left_front_hinge" type="continuous">
        <parent link="base_link"/>
        <child link="left_front"/>
        <origin rpy="0 0 0" xyz="1.3 0.9 0.145" />
        <axis xyz="0 1 0"/>
        <limit effort="100" velocity="100.0"  />
      </joint>
      
      <joint name="left_rear_hinge" type="continuous">
        <parent link="base_link"/>
        <child link="left_rear"/>
        <origin rpy="0 0 0" xyz="-1.225 0.9 0.145" />
        <axis xyz="0 1 0"/>
        <limit effort="100" velocity="100.0"  />
      </joint>
      
      <joint name="right_front_hinge" type="continuous">
        <parent link="base_link"/>
        <child link="right_front"/>
        <origin rpy="0 0 0" xyz="1.3 -0.9 0.145" />
        <axis xyz="0 1 0"/>
        <limit effort="100" velocity="100.0"  />
      </joint>
      
      <joint name="right_rear_hinge" type="continuous">
        <parent link="base_link"/>
        <child link="right_rear"/>
        <origin rpy="0 0 0" xyz="-1.225 -0.9 0.145" />
        <axis xyz="0 1 0"/>
        <limit effort="100" velocity="100.0"  />
      </joint>
 <!-- /// Camera /// -->     
      <joint name="camera_joint" type="fixed">
    <axis xyz="0 1 0" />
    <origin xyz="-0.05 0 1.1255" rpy="0 0 0"/>
    <parent link="base_link"/>
    <child link="camera_link"/>
  </joint>


  <!-- Camera -->
  <link name="camera_link">
    <collision>
      <origin xyz="0 0 0" rpy="0 0 0"/>
      <geometry>
    <box size="0.05 0.05 0.05"/>
      </geometry>
    </collision>

    <visual>
      <origin xyz="0 0 0" rpy="0 0 0"/>
      <geometry>
    <box size="0.05 0.05 0.05"/>
      </geometry>
      <material name="red"/>
    </visual>

    <inertial>
      <mass value="1e-5" />
      <origin xyz="0 0 0" rpy="0 0 0"/>
      <inertia ixx="1e-6" ixy="0" ixz="0" iyy="1e-6" iyz="0" izz="1e-6" />
    </inertial>
  </link>
  
  <!-- camera -->
  <gazebo reference="camera_link">
    <sensor type="camera" name="camera1">
      <update_rate>30.0</update_rate>
      <camera name="head">
        <horizontal_fov>1.3962634</horizontal_fov>
        <image>
          <width>800</width>
          <height>800</height>
          <format>R8G8B8</format>
        </image>
        <clip>
          <near>0.02</near>
          <far>300</far>
        </clip>
      </camera>
      <plugin name="camera_controller" filename="libgazebo_ros_camera.so">
        <alwaysOn>true</alwaysOn>
        <updateRate>30.0</updateRate>
        <cameraName>turobot/camera1</cameraName>
        <imageTopicName>image_raw</imageTopicName>
        <cameraInfoTopicName>camera_info</cameraInfoTopicName>
         <frameName>camera_link</frameName>
        <hackBaseline>0.07</hackBaseline>
        <distortionK1>0.0</distortionK1>
        <distortionK2>0.0</distortionK2>
        <distortionK3>0.0</distortionK3>
        <distortionT1>0.0</distortionT1>
        <distortionT2>0.0</distortionT2>
      </plugin>
    </sensor>
  </gazebo>
  
  
   <!-- /// Camera /// -->     
      <joint name="camera_joint1" type="fixed">
    <axis xyz="0 1 0" />
    <origin xyz="-0.95 0 1.1" rpy="0 0 3.14"/>
    <parent link="base_link"/>
    <child link="camera_link1"/>
  </joint>


  <!-- Camera -->
  <link name="camera_link1">
    <collision>
      <origin xyz="0 0 0" rpy="0 0 0"/>
      <geometry>
    <box size="0.05 0.05 0.05"/>
      </geometry>
    </collision>

    <visual>
      <origin xyz="0 0 0" rpy="0 0 0"/>
      <geometry>
    <box size="0.05 0.05 0.05"/>
      </geometry>
      <material name="red"/>
    </visual>

    <inertial>
      <mass value="1e-5" />
      <origin xyz="0 0 0" rpy="0 0 0"/>
      <inertia ixx="1e-6" ixy="0" ixz="0" iyy="1e-6" iyz="0" izz="1e-6" />
    </inertial>
  </link>
  
  <!-- camera -->
  <gazebo reference="camera_link1">
    <sensor type="camera" name="camera2">
      <update_rate>30.0</update_rate>
      <camera name="head">
        <horizontal_fov>1.3962634</horizontal_fov>
        <image>
          <width>800</width>
          <height>800</height>
          <format>R8G8B8</format>
        </image>
        <clip>
          <near>0.02</near>
          <far>300</far>
        </clip>
      </camera>
      <plugin name="camera_controller1" filename="libgazebo_ros_camera.so">
        <alwaysOn>true</alwaysOn>
        <updateRate>30.0</updateRate>
        <cameraName>turobot/camera2</cameraName>
        <imageTopicName>image_raw</imageTopicName>
        <cameraInfoTopicName>camera_info</cameraInfoTopicName>
         <frameName>camera_link1</frameName>
        <hackBaseline>0.07</hackBaseline>
        <distortionK1>0.0</distortionK1>
        <distortionK2>0.0</distortionK2>
        <distortionK3>0.0</distortionK3>
        <distortionT1>0.0</distortionT1>
        <distortionT2>0.0</distortionT2>
      </plugin>
    </sensor>
  </gazebo>
  
  
  <joint name="hokuyo_joint" type="fixed">
    <axis xyz="0 1 0" />
    <origin xyz="1.2 0 0.72" rpy="0 0 0"/>
    <parent link="base_link"/>
    <child link="hokuyo_link"/>
  </joint>

  <!-- Hokuyo Laser -->
  <link name="hokuyo_link">
    <collision>
      <origin xyz="0 0 0" rpy="0 0 0"/>
      <geometry>
    <box size="0.1 0.1 0.1"/>
      </geometry>
    </collision>

    <visual>
      <origin xyz="0 0 0" rpy="0 0 0"/>
      <geometry>
        <mesh filename="package://myrobot_discription/meshes/hokuyo.dae"/>
      </geometry>
    </visual>

    <inertial>
      <mass value="1e-5" />
      <origin xyz="0 0 0" rpy="0 0 0"/>
      <inertia ixx="1e-6" ixy="0" ixz="0" iyy="1e-6" iyz="0" izz="1e-6" />
    </inertial>
  </link>

  <!-- hokuyo -->
  <gazebo reference="hokuyo_link">
    <sensor type="ray" name="head_hokuyo_sensor">
      <pose>0 0 0 0 0 0</pose>
      <visualize>true</visualize>
      <update_rate>40</update_rate>
      <ray>
        <scan>
          <horizontal>
            <samples>720</samples>
            <resolution>1</resolution>
            <min_angle>-1.570796</min_angle>
            <max_angle>1.570796</max_angle>
          </horizontal>
        </scan>
        <range>
          <min>0.10</min>
          <max>30.0</max>
          <resolution>0.01</resolution>
        </range>
      </ray>
      <plugin name="gazebo_ros_head_hokuyo_controller" filename="libgazebo_ros_laser.so">
        <topicName>/turobot/laser/scan</topicName>
        <frameName>hokuyo_link</frameName>
      </plugin>
    </sensor>
  </gazebo>
  
<!--
<gazebo>
  <plugin name="differential_drive_controller" filename="libgazebo_ros_diff_drive.so">
    <alwaysOn>true</alwaysOn>
    <updateRate>100</updateRate>
    <leftJoint>left_rear_hinge</leftJoint>
    <rightJoint>right_rear_hinge</rightJoint>
    <wheelSeparation>0.5380</wheelSeparation>
    <wheelDiameter>0.2410</wheelDiameter>
    <torque>20</torque>
    <commandTopic>cmd_vel</commandTopic>
    <odometryTopic>odom</odometryTopic>
    <odometryFrame>odom</odometryFrame>
    <robotBaseFrame>base_link</robotBaseFrame>
  </plugin>
</gazebo> 
-->


  <transmission name="tran1">
    <type>transmission_interface/SimpleTransmission</type>
    <joint name="left_front_hinge">
      <hardwareInterface>hardware_interface/EffortJointInterface</hardwareInterface>
    </joint>
    <actuator name="motor1">
      <hardwareInterface>hardware_interface/EffortJointInterface</hardwareInterface>
      <mechanicalReduction>10</mechanicalReduction>
    </actuator>
  </transmission>

  <transmission name="tran2">
    <type>transmission_interface/SimpleTransmission</type>
    <joint name="left_rear_hinge">
      <hardwareInterface>hardware_interface/EffortJointInterface</hardwareInterface>
    </joint>
    <actuator name="motor2">
      <hardwareInterface>hardware_interface/EffortJointInterface</hardwareInterface>
      <mechanicalReduction>10</mechanicalReduction>
    </actuator>
  </transmission>

  <transmission name="tran3">
    <type>transmission_interface/SimpleTransmission</type>
    <joint name="right_front_hinge">
      <hardwareInterface>hardware_interface/EffortJointInterface</hardwareInterface>
    </joint>
    <actuator name="motor3">
      <hardwareInterface>hardware_interface/EffortJointInterface</hardwareInterface>
      <mechanicalReduction>10</mechanicalReduction>
    </actuator>
  </transmission>

  <transmission name="tran4">
    <type>transmission_interface/SimpleTransmission</type>
    <joint name="right_rear_hinge">
      <hardwareInterface>hardware_interface/EffortJointInterface</hardwareInterface>
    </joint>
    <actuator name="motor4">
      <hardwareInterface>hardware_interface/EffortJointInterface</hardwareInterface>
      <mechanicalReduction>10</mechanicalReduction>
    </actuator>
  </transmission>

<gazebo>
    <plugin name="gazebo_ros_control" filename="libgazebo_ros_control.so">
      <robotNamespace>/turobot</robotNamespace>
    </plugin>
  </gazebo>

<gazebo>
  <plugin name="differential_drive_controller" filename="libgazebo_ros_diff_drive.so">
    <alwaysOn>true</alwaysOn>
    <updateRate>10000</updateRate>
    <leftJoint>left_front_hinge</leftJoint>
    <rightJoint>right_front_hinge</rightJoint>
    <wheelSeparation>1.8</wheelSeparation>
    <wheelDiameter>0.62</wheelDiameter>
    <torque>20</torque>
    <commandTopic>turobot/cmd_vel</commandTopic>
    <odometryTopic>turobot/odom_diffdrive</odometryTopic>
    <odometryFrame>odom</odometryFrame>
    <robotBaseFrame>base_link</robotBaseFrame>
  </plugin>
</gazebo>
</robot>
